{"errorMessage": "module 'os' has no attribute 'add_dll_directory'", "errorType": "AttributeError", "requestId": "", "stackTrace": ["  File \"/var/lang/lib/python3.12/importlib/__init__.py\", line 90, in import_module\n    return _bootstrap._gcd_import(name[level:], package, level)\n", "  File \"<frozen importlib._bootstrap>\", line 1387, in _gcd_import\n", "  File \"<frozen importlib._bootstrap>\", line 1360, in _find_and_load\n", "  File \"<frozen importlib._bootstrap>\", line 1310, in _find_and_load_unlocked\n", "  File \"<frozen importlib._bootstrap>\", line 488, in _call_with_frames_removed\n", "  File \"<frozen importlib._bootstrap>\", line 1387, in _gcd_import\n", "  File \"<frozen importlib._bootstrap>\", line 1360, in _find_and_load\n", "  File \"<frozen importlib._bootstrap>\", line 1331, in _find_and_load_unlocked\n", "  File \"<frozen importlib._bootstrap>\", line 935, in _load_unlocked\n", "  File \"<frozen importlib._bootstrap_external>\", line 999, in exec_module\n", "  File \"<frozen importlib._bootstrap>\", line 488, in _call_with_frames_removed\n", "  File \"/var/task/src/__init__.py\", line 13, in <module>\n    from . import chart_generator\n", "  File \"/var/task/src/chart_generator.py\", line 8, in <module>\n    import matplotlib.pyplot as plt\n", "  File \"/var/task/matplotlib/__init__.py\", line 161, in <module>\n    from . import _api, _version, cbook, _docstring, rcsetup\n", "  File \"/var/task/matplotlib/cbook.py\", line 24, in <module>\n    import numpy as np\n", "  File \"/var/task/numpy/__init__.py\", line 97, in <module>\n    _delvewheel_patch_1_10_1()\n", "  File \"/var/task/numpy/__init__.py\", line 94, in _delvewheel_patch_1_10_1\n    os.add_dll_directory(libs_dir)\n"]}